Workbook

Sheet Assumptions
A1: Visa Inc. (V)
A2: Discounted Cash Flow Model
A3: USD in millions, except per share data
A4: Fiscal year ends September 30
A6: Fiscal Year | B6: Units | C6: ="FY"&(2021+COLUMN()-3)&"A" -> FY2021A | D6: ="FY"&(2021+COLUMN()-3)&"A" -> FY2022A | E6: ="FY"&(2021+COLUMN()-3)&"A" -> FY2023A | F6: ="FY"&(2021+COLUMN()-3)&"A" -> FY2024A | G6: ="FY"&(2021+COLUMN()-3)&"A" -> FY2025A | H6: ="FY"&(2026+COLUMN()-8)&"E" -> FY2026E | I6: ="FY"&(2026+COLUMN()-8)&"E" -> FY2027E | J6: ="FY"&(2026+COLUMN()-8)&"E" -> FY2028E | K6: ="FY"&(2026+COLUMN()-8)&"E" -> FY2029E | L6: ="FY"&(2026+COLUMN()-8)&"E" -> FY2030E
A7: Operating Drivers
A8: Revenue growth % | B8: % | D8: =Historicals!D8/Historicals!C8-1 -> 0.2159303 | E8: =Historicals!E8/Historicals!D8-1 -> 0.11405664 | F8: =Historicals!F8/Historicals!E8-1 -> 0.10023581 | G8: =Historicals!G8/Historicals!F8-1 -> 0.11339977 | H8: =C24 -> 0.144372 | I8: 0.11 | J8: 0.105 | K8: =AVERAGE(J8,L8) -> 0.0925 | L8: 0.08 | N8: FY2026: consensus (10.8), slowing down from 15% as competition gets harder
A9: Operating margin % (reported) | B9: % | C9: =Historicals!C16/Historicals!C8 -> 0.65563161 | D9: =Historicals!D16/Historicals!D8 -> 0.64186285 | E9: =Historicals!E16/Historicals!E8 -> 0.64312621 | F9: =Historicals!F16/Historicals!F8 -> 0.65676669 | G9: =Historicals!G16/Historicals!G8 -> 0.59985 | H9: =H10-H16 -> 0.63127158 | I9: =I10-I16 -> 0.63127158 | J9: =J10-J16 -> 0.63127158 | K9: =K10-K16 -> 0.63127158 | L9: =L10-L16 -> 0.63127158
A10: Operating margin % (excel. litigation) | B10: % | C10: =(Historicals!C16+Historicals!C15)/Historicals!C8 -> 0.65575607 | D10: =(Historicals!D16+Historicals!D15)/Historicals!D8 -> 0.67147731 | E10: =(Historicals!E16+Historicals!E15)/Historicals!E8 -> 0.67151563 | F10: =(Historicals!F16+Historicals!F15)/Historicals!F8 -> 0.66962645 | G10: =(Historicals!G16+Historicals!G15)/Historicals!G8 -> 0.6639 | H10: 0.665 | I10: 0.665 | J10: 0.665 | K10: 0.665 | L10: 0.665
A11: D&A of revenue | B11: % | C11: =Historicals!C22/Historicals!C8 -> 0.033354076 | D11: =Historicals!D22/Historicals!D8 -> 0.02937564 | E11: =Historicals!E22/Historicals!E8 -> 0.028879429 | F11: =Historicals!F22/Historicals!F8 -> 0.028781384 | G11: =Historicals!G22/Historicals!G8 -> 0.0305 | H11: =AVERAGE(E11:G11) -> 0.029386938 | I11: =H11 -> 0.029386938 | J11: =I11 -> 0.029386938 | K11: =J11 -> 0.029386938 | L11: =K11 -> 0.029386938
A12: Capex % of revenue | B12: % | C12: =Historicals!C24/Historicals!C8 -> 0.029247044 | D12: =Historicals!D24/Historicals!D8 -> 0.033094507 | E12: =Historicals!E24/Historicals!E8 -> 0.032431936 | F12: =Historicals!F24/Historicals!F8 -> 0.034988588 | G12: =Historicals!G24/Historicals!G8 -> 0.03705 | H12: =G12 -> 0.03705 | I12: =H12 -> 0.03705 | J12: =I12 -> 0.03705 | K12: =J12 -> 0.03705 | L12: =K12 -> 0.03705
A13: Share-based comp % of revenue | B13: % | C13: =Historicals!C23/Historicals!C8 -> 0.022484962 | D13: =Historicals!D23/Historicals!D8 -> 0.020539065 | E13: =Historicals!E23/Historicals!E8 -> 0.023428169 | F13: =Historicals!F23/Historicals!F8 -> 0.023659745 | G13: =Historicals!G23/Historicals!G8 -> 0.022425
A14: Tax rate % | B14: % | H14: 0.175 | I14: =H14 -> 0.175 | J14: =I14 -> 0.175 | K14: =J14 -> 0.175 | L14: =K14 -> 0.175
A15: Change in NWC % of change in revenue | B15: % | H15: 0 | I15: =H15 -> 0 | J15: =I15 -> 0 | K15: =J15 -> 0 | L15: =K15 -> 0
A16: Litigation provision % of revenue | C16: =Historicals!C15/Historicals!C8 -> 0.00012445551 | D16: =Historicals!D15/Historicals!D8 -> 0.029614466 | E16: =Historicals!E15/Historicals!E8 -> 0.028389428 | F16: =Historicals!F15/Historicals!F8 -> 0.012859767 | G16: =Historicals!G15/Historicals!G8 -> 0.06405 | H16: =AVERAGE(D16:G16) -> 0.033728415 | I16: =H16 -> 0.033728415 | J16: =I16 -> 0.033728415 | K16: =J16 -> 0.033728415 | L16: =K16 -> 0.033728415
A18: FY2026 growth check
A19: 9M FY2026 net revenue | B19: $mm | C19: 33764
A20: 9M FY2025 net revenue | B20: $mm | C20: 29276
A21: 9M growth % | B21: % | C21: =C19/C20-1 -> 0.15329963
A22: Q4 FY2026 growth assumption | C22: 0.12
A23: FY2026E Revenue | C23: =C19+(Historicals!G8-C20)*(1+C22) -> 45774.88
A24: FY2026E growth % | C24: =C23/Historicals!G8-1 -> 0.144372

Sheet Historicals
A1: Visa Inc. (V)
A2: Discounted Cash Flow Model
A3: USD in millions, except per share data
A4: Fiscal year ends September 30
A6: Fiscal Year | B6: Units | C6: ="FY"&(2021+COLUMN()-3)&"A" -> FY2021A | D6: ="FY"&(2021+COLUMN()-3)&"A" -> FY2022A | E6: ="FY"&(2021+COLUMN()-3)&"A" -> FY2023A | F6: ="FY"&(2021+COLUMN()-3)&"A" -> FY2024A | G6: ="FY"&(2021+COLUMN()-3)&"A" -> FY2025A | H6: ="FY"&(2026+COLUMN()-8)&"E" -> FY2026E | I6: ="FY"&(2026+COLUMN()-8)&"E" -> FY2027E | J6: ="FY"&(2026+COLUMN()-8)&"E" -> FY2028E | K6: ="FY"&(2026+COLUMN()-8)&"E" -> FY2029E | L6: ="FY"&(2026+COLUMN()-8)&"E" -> FY2030E
A8: Net Revenue | B8: $mm | C8: 24105 | D8: 29310 | E8: 32653 | F8: 35926 | G8: 40000
A9: Personnel | B9: $mm | C9: 4240 | D9: 4990 | E9: 5831 | F9: 6264 | G9: 6961
A10: Marketing | B10: $mm | C10: 1136 | D10: 1336 | E10: 1341 | F10: 1560 | G10: 1684
A11: Network and processing | B11: $mm | C11: 730 | D11: 743 | E11: 736 | F11: 778 | G11: 894
A12: Professional fees | B12: $mm | C12: 403 | D12: 505 | E12: 545 | F12: 635 | G12: 759
A13: Depreciation and amoritization | B13: $mm | C13: 804 | D13: 861 | E13: 943 | F13: 1034 | G13: 1220
A14: General and administrative | B14: $mm | C14: 985 | D14: 1194 | E14: 1330 | F14: 1598 | G14: 1926
A15: Litigation provision | B15: $mm | C15: 3 | D15: 868 | E15: 927 | F15: 462 | G15: 2562
A16: Operating Income per 10-K | B16: $mm | C16: 15804 | D16: 18813 | E16: 21000 | F16: 23595 | G16: 23994
A17: Total Operating Expenses | B17: $mm | C17: =SUM(C9:C15) -> 8301 | D17: =SUM(D9:D15) -> 10497 | E17: =SUM(E9:E15) -> 11653 | F17: =SUM(F9:F15) -> 12331 | G17: =SUM(G9:G15) -> 16006
A18: Operating Income (calculated) | B18: $mm | C18: =C8-C17 -> 15804 | D18: =D8-D17 -> 18813 | E18: =E8-E17 -> 21000 | F18: =F8-F17 -> 23595 | G18: =G8-G17 -> 23994
A19: Check (should be 0) | B19: $mm | C19: =C18-C16 -> 0 | D19: =D18-D16 -> 0 | E19: =E18-E16 -> 0 | F19: =F18-F16 -> 0 | G19: =G18-G16 -> 0
A21: Cash Flow Items
A22: D&A (cash flow statement) | B22: $mm | C22: 804 | D22: 861 | E22: 943 | F22: 1034 | G22: 1220
A23: Share-based compensation | B23: $mm | C23: 542 | D23: 602 | E23: 765 | F23: 850 | G23: 897
A24: Capital Expenditures | B24: $mm | C24: 705 | D24: 970 | E24: 1059 | F24: 1257 | G24: 1482
A27: Balance Sheet Items | B27: Units | C27: 46203
A28: Cash and cash equivalents | B28: $mm | C28: 12359
A29: Investment securities, current | B29: $mm | C29: 1433
A30: Investment securities, non-current | B30: $mm | C30: 150
A31: Total cash investments | B31: $mm | C31: =SUM(C28:C30) -> 13942
A33: Current maturities of long-term debt | B33: $mm | C33: 2996
A34: Long-term debt | B34: $mm | C34: 20862
A35: Total debt | B35: $mm | C35: =SUM(C33:C34) -> 23858
A37: Diluted shares, as converted Class A | B37: mm shares | C37: 1898

Sheet Projections
A1: Visa Inc. (V)
A2: Discounted Cash Flow Model
A3: USD in millions, except per share data
A4: Fiscal year ends September 30
A6: Fiscal Year | B6: Units | C6: ="FY"&(2021+COLUMN()-3)&"A" -> FY2021A | D6: ="FY"&(2021+COLUMN()-3)&"A" -> FY2022A | E6: ="FY"&(2021+COLUMN()-3)&"A" -> FY2023A | F6: ="FY"&(2021+COLUMN()-3)&"A" -> FY2024A | G6: ="FY"&(2021+COLUMN()-3)&"A" -> FY2025A | H6: ="FY"&(2026+COLUMN()-8)&"E" -> FY2026E | I6: ="FY"&(2026+COLUMN()-8)&"E" -> FY2027E | J6: ="FY"&(2026+COLUMN()-8)&"E" -> FY2028E | K6: ="FY"&(2026+COLUMN()-8)&"E" -> FY2029E | L6: ="FY"&(2026+COLUMN()-8)&"E" -> FY2030E
A7: Operating Build
A8: Net revenue | B8: $mm | C8: =Historicals!C8 -> 24105 | D8: =Historicals!D8 -> 29310 | E8: =Historicals!E8 -> 32653 | F8: =Historicals!F8 -> 35926 | G8: =Historicals!G8 -> 40000 | H8: =G8*(1+Assumptions!H8) -> 45774.88 | I8: =H8*(1+Assumptions!I8) -> 50810.117 | J8: =I8*(1+Assumptions!J8) -> 56145.179 | K8: =J8*(1+Assumptions!K8) -> 61338.608 | L8: =K8*(1+Assumptions!L8) -> 66245.697
A9: Revenue growth % | B9: % | D9: =D8/C8-1 -> 0.2159303 | E9: =E8/D8-1 -> 0.11405664 | F9: =F8/E8-1 -> 0.10023581 | G9: =G8/F8-1 -> 0.11339977 | H9: =H8/G8-1 -> 0.144372 | I9: =I8/H8-1 -> 0.11 | J9: =J8/I8-1 -> 0.105 | K9: =K8/J8-1 -> 0.0925 | L9: =L8/K8-1 -> 0.08
A10: Operating income (EBIT) | B10: $mm | C10: =Historicals!C16 -> 15804 | D10: =Historicals!D16 -> 18813 | E10: =Historicals!E16 -> 21000 | F10: =Historicals!F16 -> 23595 | G10: =Historicals!G16 -> 23994 | H10: =H8*Assumptions!H9 -> 28896.381 | I10: =I8*Assumptions!I9 -> 32074.983 | J10: =J8*Assumptions!J9 -> 35442.856 | K10: =K8*Assumptions!K9 -> 38721.32 | L10: =L8*Assumptions!L9 -> 41819.026
A11: Operating margin % | B11: % | C11: =C10/C8 -> 0.65563161 | D11: =D10/D8 -> 0.64186285 | E11: =E10/E8 -> 0.64312621 | F11: =F10/F8 -> 0.65676669 | G11: =G10/G8 -> 0.59985 | H11: =H10/H8 -> 0.63127158 | I11: =I10/I8 -> 0.63127158 | J11: =J10/J8 -> 0.63127158 | ... L11: =L10/L8 -> 0.63127158
A13: Free Cash Flow Build
A14: EBIT | H14: =H10 -> 28896.381 | I14: =I10 -> 32074.983 | J14: =J10 -> 35442.856 | K14: =K10 -> 38721.32 | L14: =L10 -> 41819.026
A15: Less: taxes on EBIT | H15: =H14*Assumptions!H14 -> 5056.8667 | I15: =I14*Assumptions!I14 -> 5613.122 | J15: =J14*Assumptions!J14 -> 6202.4998 | K15: =K14*Assumptions!K14 -> 6776.2311 | L15: =L14*Assumptions!L14 -> 7318.3295
A16: NOPAT | H16: =H14-H15 -> 23839.514 | I16: =I14-I15 -> 26461.861 | J16: =J14-J15 -> 29240.356 | K16: =K14-K15 -> 31945.089 | L16: =L14-L15 -> 34500.696
A17: Plus: D&A | C17: =Historicals!C22 -> 804 | D17: =Historicals!D22 -> 861 | E17: =Historicals!E22 -> 943 | F17: =Historicals!F22 -> 1034 | G17: =Historicals!G22 -> 1220 | H17: =H8*Assumptions!H11 -> 1345.1835 | I17: =I8*Assumptions!I11 -> 1493.1537 | J17: =J8*Assumptions!J11 -> 1649.9349 | K17: =K8*Assumptions!K11 -> 1802.5539 | L17: =L8*Assumptions!L11 -> 1946.7582
A18: Less: capex | C18: =Historicals!C24 -> 705 | D18: =Historicals!D24 -> 970 | E18: =Historicals!E24 -> 1059 | F18: =Historicals!F24 -> 1257 | G18: =Historicals!G24 -> 1482 | H18: =H8*Assumptions!H12 -> 1695.9593 | I18: =I8*Assumptions!I12 -> 1882.5148 | J18: =J8*Assumptions!J12 -> 2080.1789 | K18: =K8*Assumptions!K12 -> 2272.5954 | L18: =L8*Assumptions!L12 -> 2454.4031
A19: Less: increase in NWC | H19: =(H8-G8)*Assumptions!H15 -> 0 | I19: =(I8-H8)*Assumptions!I15 -> 0 | J19: =(J8-I8)*Assumptions!J15 -> 0 | K19: =(K8-J8)*Assumptions!K15 -> 0 | L19: =(L8-K8)*Assumptions!L15 -> 0
A20: Unlevered free cash flow | H20: =H16+H17-H18-H19 -> 23488.739 | I20: =I16+I17-I18-I19 -> 26072.5 | J20: =J16+J17-J18-J19 -> 28810.112 | K20: =K16+K17-K18-K19 -> 31475.048 | L20: =L16+L17-L18-L19 -> 33993.052
A21: FCF margin % | H21: =H20/H8 -> 0.513136 | I21: =I20/I8 -> 0.513136 | J21: =J20/J8 -> 0.513136 | K21: =K20/K8 -> 0.513136 | L21: =L20/L8 -> 0.513136

Sheet DCF
A1: Visa Inc. (V)
A2: Discounted Cash Flow Model
A3: USD in millions, except per share data
A4: Fiscal year ends September 30
A6: Fiscal Year | B6: Units | C6: FY2021A | D6: FY2022A | E6: FY2023A | F6: FY2024A | G6: FY2025A | H6: FY2026E | I6: FY2027E | J6: FY2028E | K6: FY2029E | L6: FY2030E
A7: Inputs
A8: WACC | B8: % | C8: =WACC!C26 -> 0.089417386
A9: Terminal growth rate | B9: % | C9: 0.03
A10: Valuation date | C10: 46295
A11: Check: growth below WACC | C11: =IF(C9<C8, "OK", "ERROR") -> OK
A13: Discounting, mid year
A14: Unlevered free cash flow | B14: $mm | I14: =Projections!I20 -> 26072.5 | J14: =Projections!J20 -> 28810.112 | K14: =Projections!K20 -> 31475.048 | L14: =Projections!L20 -> 33993.052
A15: Discount period | B15: years | I15: 0.5 | J15: =I15+1 -> 1.5 | K15: =J15+1 -> 2.5 | L15: =K15+1 -> 3.5
A16: Discount factor | B16: x | I16: =1/(1+$C$8)^I15 -> 0.95808237 | J16: =1/(1+$C$8)^J15 -> 0.87944472 | K16: =1/(1+$C$8)^K15 -> 0.80726151 | L16: =1/(1+$C$8)^L15 -> 0.74100296
A17: Present value of FCF | B17: $mm | I17: =I14*I16 -> 24979.602 | J17: =J14*J16 -> 25336.901 | K17: =K14*K16 -> 25408.594 | L17: =L14*L16 -> 25188.952
A18: Sum of PV of FCF | B18: $mm | C18: =SUM(I17:L17) -> 100914.05
A20: Terminal Value
A21: Final-year FCF | B21: $mm | C21: =L14 -> 33993.052
A22: Terminal value at FY2030 | B22: $mm | C22: =C21*(1+C9)/(C8-C9) -> 589269.32
A23: Discount factor for TV | B23: x | C23: =L16 -> 0.74100296
A24: PV of terminal value | B24: $mm | C24: =C22*C23 -> 436650.31
A25: TV as % of EV | B25: % | C25: =C24/C28 -> 0.81227541
A27: Equity bridge
A28: Enterprise value | B28: $mm | C28: =C18+C24 -> 537564.36
A29: Less: total debt | B29: $mm | C29: =Historicals!C35 -> 23858
A30: Plus: cash and investments | B30: $mm | C30: =Historicals!C31 -> 13942
A31: Equity Value | B31: $mm | C31: =C28-C29+C30 -> 527648.36
A32: Diluted shares | B32: mm | C32: =Historicals!C37 -> 1898
A33: Implied share price | B33: $ | C33: =C31/C32 -> 278.0023
A34: Current share price | B34: $ | C34: =WACC!C18 -> 360.66
A35: Upside / (downside) | B35: % | C35: =C33/C34-1 -> -0.22918456
A37: Exit multiple cross-check
A38: FY2030E EBITDA | B38: $mm | C38: =Projections!L10+Projections!L17 -> 43765.784
A39: Implied exit multiple (perpetuity method) | B39: x | C39: =C22*(1+C8)^0.5/C38 -> 14.053234
A40: Exit multiple (EV / EBITDA) | B40: x | C40: 18
A41: Terminal value (exit multiple) | B41: $mm | C41: =C38*C40 -> 787784.11
A42: Discount factor (end of FY2030) | B42: x | C42: =1/(1+C8)^(L15+0.5) -> 0.70994187
A43: PV of terminal value | B43: $mm | C43: =C41*C42 -> 559280.93
A44: Enterprise value | B44: $mm | C44: =C18+C43 -> 660194.98
A45: Equity Value | B45: $mm | C45: =C44-C29+C30 -> 650278.98
...

Sheet WACC
A1: Visa Inc. (V)
A2: Discounted Cash Flow Model
A3: USD in millions, except per share data
A4: Fiscal year ends September 30
A6: Cost of Equity | B6: Unit | N6: ^TNX, 10/2/2026
A7: Risk-free rate (10-year Treasury) | B7: % | C7: 0.0528
A8: Equity risk premium | B8: % | C8: 0.05
A9: Beta | B9: x | C9: 0.76
A10: Cost of equity | B10: % | C10: =C7+C9*C8 -> 0.0908
A12: Cost of Debt
A13: Pre-tax cost of debt | B13: % | C13: =C7+C28 -> 0.0603
A14: Tax rate | B14: % | C14: =Assumptions!H14 -> 0.175
A15: After-tax cost of debt | B15: % | C15: =C13*(1-C14) -> 0.0497475
A17: Capital Structure
A18: Share price | B18: $ | C18: 360.66
A19: Diluted shares | B19: mm | C19: =Historicals!C37 -> 1898
A20: Market capitalization | B20: $mm | C20: =C18*C19 -> 684532.68
A21: Total debt | B21: $mm | C21: =Historicals!C35 -> 23858
A22: Total capitalization | B22: $mm | C22: =C20+C21 -> 708390.68
A23: Equity weight | B23: % | C23: =C20/C22 -> 0.96632084
A24: Debt weight | B24: % | C24: =C21/C22 -> 0.033679156
A26: WACC | B26: % | C26: =C23*C10+C24*C15 -> 0.089417386
A28: Credit spread | B28: % | C28: 0.0075

Sheet Sensitivity
A1: Visa Inc. (V)
A2: Discounted Cash Flow Model
A3: USD in millions, except per share data
A4: Fiscal year ends September 30
A6: Sensitivity 1: Implied share prices, perpetuity method
B8: WACC \ G | C8: =D8-0.5% -> 0.02 | D8: =E8-0.5% -> 0.025 | E8: =DCF!C9 -> 0.03 | F8: =E8+0.5% -> 0.035 | G8: =F8+0.5% -> 0.04
B9: =B10-0.5% -> 0.079417386 | C9: {=(SUMPRODUCT(DCF!$I$14:$L$14/(1+$B9)^DCF!$I$15:$L$15)+DCF!$L$14*(1+C$8)/($B9-C$8)/(1+$B9)^DCF!$L$15-DCF!$C$29+DCF!$C$30)/DCF!$C$32} -> 284.23615 | D9: {=(SUMPRODUCT(DCF!$I$14:$L$14/(1+$B9)^DCF!$I$15:$L$15)+DCF!$L$14*(1+D$8)/($B9-D$8)/(1+$B9)^DCF!$L$15-DCF!$C$29+DCF!$C$30)/DCF!$C$32} -> 307.11526 | E9: {=(SUMPRODUCT(DCF!$I$14:$L$14/(1+$B9)^DCF!$I$15:$L$15)+DCF!$L$14*(1+E$8)/($B9-E$8)/(1+$B9)^DCF!$L$15-DCF!$C$29+DCF!$C$30)/DCF!$C$32} -> 334.62415 | F9: {=(SUMPRODUCT(DCF!$I$14:$L$14/(1+$B9)^DCF!$I$15:$L$15)+DCF!$L$14*(1+F$8)/($B9-F$8)/(1+$B9)^DCF!$L$15-DCF!$C$29+DCF!$C$30)/DCF!$C$32} -> 368.3263 | G9: {=(SUMPRODUCT(DCF!$I$14:$L$14/(1+$B9)^DCF!$I$15:$L$15)+DCF!$L$14*(1+G$8)/($B9-G$8)/(1+$B9)^DCF!$L$15-DCF!$C$29+DCF!$C$30)/DCF!$C$32} -> 410.57853
B10: =B11-0.5% -> 0.084417386 | C10: {=(SUMPRODUCT(DCF!$I$14:$L$14/(1+$B10)^DCF!$I$15:$L$15)+DCF!$L$14*(1+C$8)/($B10-C$8)/(1+$B10)^DCF!$L$15-DCF!$C$29+DCF!$C$30)/DCF!$C$32} -> 261.98903 | D10: {=(SUMPRODUCT(DCF!$I$14:$L$14/(1+$B10)^DCF!$I$15:$L$15)+DCF!$L$14*(1+D$8)/($B10-D$8)/(1+$B10)^DCF!$L$15-DCF!$C$29+DCF!$C$30)/DCF!$C$32} -> 281.09443 | E10: {=(SUMPRODUCT(DCF!$I$14:$L$14/(1+$B10)^DCF!$I$15:$L$15)+DCF!$L$14*(1+E$8)/($B10-E$8)/(1+$B10)^DCF!$L$15-DCF!$C$29+DCF!$C$30)/DCF!$C$32} -> 303.71073 | F10: {=(SUMPRODUCT(DCF!$I$14:$L$14/(1+$B10)^DCF!$I$15:$L$15)+DCF!$L$14*(1+F$8)/($B10-F$8)/(1+$B10)^DCF!$L$15-DCF!$C$29+DCF!$C$30)/DCF!$C$32} -> 330.90362 | G10: {=(SUMPRODUCT(DCF!$I$14:$L$14/(1+$B10)^DCF!$I$15:$L$15)+DCF!$L$14*(1+G$8)/($B10-G$8)/(1+$B10)^DCF!$L$15-DCF!$C$29+DCF!$C$30)/DCF!$C$32} -> 364.21863
B11: =DCF!C8 -> 0.089417386 | C11: {=(SUMPRODUCT(DCF!$I$14:$L$14/(1+$B11)^DCF!$I$15:$L$15)+DCF!$L$14*(1+C$8)/($B11-C$8)/(1+$B11)^DCF!$L$15-DCF!$C$29+DCF!$C$30)/DCF!$C$32} -> 242.9492 | D11: {=(SUMPRODUCT(DCF!$I$14:$L$14/(1+$B11)^DCF!$I$15:$L$15)+DCF!$L$14*(1+D$8)/($B11-D$8)/(1+$B11)^DCF!$L$15-DCF!$C$29+DCF!$C$30)/DCF!$C$32} -> 259.11536 | E11: {=(SUMPRODUCT(DCF!$I$14:$L$14/(1+$B11)^DCF!$I$15:$L$15)+DCF!$L$14*(1+E$8)/($B11-E$8)/(1+$B11)^DCF!$L$15-DCF!$C$29+DCF!$C$30)/DCF!$C$32} -> 278.0023 | F11: {=(SUMPRODUCT(DCF!$I$14:$L$14/(1+$B11)^DCF!$I$15:$L$15)+DCF!$L$14*(1+F$8)/($B11-F$8)/(1+$B11)^DCF!$L$15-DCF!$C$29+DCF!$C$30)/DCF!$C$32} -> 300.35999 | G11: {=(SUMPRODUCT(DCF!$I$14:$L$14/(1+$B11)^DCF!$I$15:$L$15)+DCF!$L$14*(1+G$8)/($B11-G$8)/(1+$B11)^DCF!$L$15-DCF!$C$29+DCF!$C$30)/DCF!$C$32} -> 327.24194
B12: =B11+0.5% -> 0.094417386 | C12: {=(SUMPRODUCT(DCF!$I$14:$L$14/(1+$B12)^DCF!$I$15:$L$15)+DCF!$L$14*(1+C$8)/($B12-C$8)/(1+$B12)^DCF!$L$15-DCF!$C$29+DCF!$C$30)/DCF!$C$32} -> 226.47013 | D12: {=(SUMPRODUCT(DCF!$I$14:$L$14/(1+$B12)^DCF!$I$15:$L$15)+DCF!$L$14*(1+D$8)/($B12-D$8)/(1+$B12)^DCF!$L$15-DCF!$C$29+DCF!$C$30)/DCF!$C$32} -> 240.30464 | E12: {=(SUMPRODUCT(DCF!$I$14:$L$14/(1+$B12)^DCF!$I$15:$L$15)+DCF!$L$14*(1+E$8)/($B12-E$8)/(1+$B12)^DCF!$L$15-DCF!$C$29+DCF!$C$30)/DCF!$C$32} -> 256.28679 | F12: {=(SUMPRODUCT(DCF!$I$14:$L$14/(1+$B12)^DCF!$I$15:$L$15)+DCF!$L$14*(1+F$8)/($B12-F$8)/(1+$B12)^DCF!$L$15-DCF!$C$29+DCF!$C$30)/DCF!$C$32} -> 274.95875 | G12: {=(SUMPRODUCT(DCF!$I$14:$L$14/(1+$B12)^DCF!$I$15:$L$15)+DCF!$L$14*(1+G$8)/($B12-G$8)/(1+$B12)^DCF!$L$15-DCF!$C$29+DCF!$C$30)/DCF!$C$32} -> 297.06195
B13: =B12+0.5% -> 0.099417386 | C13: {=(SUMPRODUCT(DCF!$I$14:$L$14/(1+$B13)^DCF!$I$15:$L$15)+DCF!$L$14*(1+C$8)/($B13-C$8)/(1+$B13)^DCF!$L$15-DCF!$C$29+DCF!$C$30)/DCF!$C$32} -> 212.06811 | D13: {=(SUMPRODUCT(DCF!$I$14:$L$14/(1+$B13)^DCF!$I$15:$L$15)+DCF!$L$14*(1+D$8)/($B13-D$8)/(1+$B13)^DCF!$L$15-DCF!$C$29+DCF!$C$30)/DCF!$C$32} -> 224.0236 | E13: {=(SUMPRODUCT(DCF!$I$14:$L$14/(1+$B13)^DCF!$I$15:$L$15)+DCF!$L$14*(1+E$8)/($B13-E$8)/(1+$B13)^DCF!$L$15-DCF!$C$29+DCF!$C$30)/DCF!$C$32} -> 237.70135 | F13: {=(SUMPRODUCT(DCF!$I$14:$L$14/(1+$B13)^DCF!$I$15:$L$15)+DCF!$L$14*(1+F$8)/($B13-F$8)/(1+$B13)^DCF!$L$15-DCF!$C$29+DCF!$C$30)/DCF!$C$32} -> 253.50241 | G13: {=(SUMPRODUCT(DCF!$I$14:$L$14/(1+$B13)^DCF!$I$15:$L$15)+DCF!$L$14*(1+G$8)/($B13-G$8)/(1+$B13)^DCF!$L$15-DCF!$C$29+DCF!$C$30)/DCF!$C$32} -> 271.9628
A16: Sensitivity 2: Implied share price, exit multiple method
B18: WACC \ multiple | C18: =D18-2 -> 14 | D18: =E18-2 -> 16 | E18: =DCF!C40 -> 18 | F18: =E18+2 -> 20 | G18: =F18+2 -> 22
B19: =B20-0.5% -> 0.079417386 | C19: {=(SUMPRODUCT(DCF!$I$14:$L$14/(1+$B19)^DCF!$I$15:$L$15)+DCF!$C$38*C$18/(1+$B19)^(DCF!$L$15+0.5)-DCF!$C$29+DCF!$C$30)/DCF!$C$32} -> 286.73686 | D19: {=(SUMPRODUCT(DCF!$I$14:$L$14/(1+$B19)^DCF!$I$15:$L$15)+DCF!$C$38*D$18/(1+$B19)^(DCF!$L$15+0.5)-DCF!$C$29+DCF!$C$30)/DCF!$C$32} -> 320.70806 | E19: {=(SUMPRODUCT(DCF!$I$14:$L$14/(1+$B19)^DCF!$I$15:$L$15)+DCF!$C$38*E$18/(1+$B19)^(DCF!$L$15+0.5)-DCF!$C$29+DCF!$C$30)/DCF!$C$32} -> 354.67926 | F19: {=(SUMPRODUCT(DCF!$I$14:$L$14/(1+$B19)^DCF!$I$15:$L$15)+DCF!$C$38*F$18/(1+$B19)^(DCF!$L$15+0.5)-DCF!$C$29+DCF!$C$30)/DCF!$C$32} -> 388.65046 | G19: {=(SUMPRODUCT(DCF!$I$14:$L$14/(1+$B19)^DCF!$I$15:$L$15)+DCF!$C$38*G$18/(1+$B19)^(DCF!$L$15+0.5)-DCF!$C$29+DCF!$C$30)/DCF!$C$32} -> 422.62165
B20: =B21-0.5% -> 0.084417386 | C20: {=(SUMPRODUCT(DCF!$I$14:$L$14/(1+$B20)^DCF!$I$15:$L$15)+DCF!$C$38*C$18/(1+$B20)^(DCF!$L$15+0.5)-DCF!$C$29+DCF!$C$30)/DCF!$C$32} -> 281.88006 | D20: {=(SUMPRODUCT(DCF!$I$14:$L$14/(1+$B20)^DCF!$I$15:$L$15)+DCF!$C$38*D$18/(1+$B20)^(DCF!$L$15+0.5)-DCF!$C$29+DCF!$C$30)/DCF!$C$32} -> 315.22904 | E20: {=(SUMPRODUCT(DCF!$I$14:$L$14/(1+$B20)^DCF!$I$15:$L$15)+DCF!$C$38*E$18/(1+$B20)^(DCF!$L$15+0.5)-DCF!$C$29+DCF!$C$30)/DCF!$C$32} -> 348.57803 | F20: {=(SUMPRODUCT(DCF!$I$14:$L$14/(1+$B20)^DCF!$I$15:$L$15)+DCF!$C$38*F$18/(1+$B20)^(DCF!$L$15+0.5)-DCF!$C$29+DCF!$C$30)/DCF!$C$32} -> 381.92701 | G20: {=(SUMPRODUCT(DCF!$I$14:$L$14/(1+$B20)^DCF!$I$15:$L$15)+DCF!$C$38*G$18/(1+$B20)^(DCF!$L$15+0.5)-DCF!$C$29+DCF!$C$30)/DCF!$C$32} -> 415.276
B21: =DCF!C8 -> 0.089417386 | C21: {=(SUMPRODUCT(DCF!$I$14:$L$14/(1+$B21)^DCF!$I$15:$L$15)+DCF!$C$38*C$18/(1+$B21)^(DCF!$L$15+0.5)-DCF!$C$29+DCF!$C$30)/DCF!$C$32} -> 277.13084 | D21: {=(SUMPRODUCT(DCF!$I$14:$L$14/(1+$B21)^DCF!$I$15:$L$15)+DCF!$C$38*D$18/(1+$B21)^(DCF!$L$15+0.5)-DCF!$C$29+DCF!$C$30)/DCF!$C$32} -> 309.87179 | E21: {=(SUMPRODUCT(DCF!$I$14:$L$14/(1+$B21)^DCF!$I$15:$L$15)+DCF!$C$38*E$18/(1+$B21)^(DCF!$L$15+0.5)-DCF!$C$29+DCF!$C$30)/DCF!$C$32} -> 342.61274 | F21: {=(SUMPRODUCT(DCF!$I$14:$L$14/(1+$B21)^DCF!$I$15:$L$15)+DCF!$C$38*F$18/(1+$B21)^(DCF!$L$15+0.5)-DCF!$C$29+DCF!$C$30)/DCF!$C$32} -> 375.35369 | G21: {=(SUMPRODUCT(DCF!$I$14:$L$14/(1+$B21)^DCF!$I$15:$L$15)+DCF!$C$38*G$18/(1+$B21)^(DCF!$L$15+0.5)-DCF!$C$29+DCF!$C$30)/DCF!$C$32} -> 408.09464
B22: =B21+0.5% -> 0.094417386 | C22: {=(SUMPRODUCT(DCF!$I$14:$L$14/(1+$B22)^DCF!$I$15:$L$15)+DCF!$C$38*C$18/(1+$B22)^(DCF!$L$15+0.5)-DCF!$C$29+DCF!$C$30)/DCF!$C$32} -> 272.48631 | D22: {=(SUMPRODUCT(DCF!$I$14:$L$14/(1+$B22)^DCF!$I$15:$L$15)+DCF!$C$38*D$18/(1+$B22)^(DCF!$L$15+0.5)-DCF!$C$29+DCF!$C$30)/DCF!$C$32} -> 304.63302 | E22: {=(SUMPRODUCT(DCF!$I$14:$L$14/(1+$B22)^DCF!$I$15:$L$15)+DCF!$C$38*E$18/(1+$B22)^(DCF!$L$15+0.5)-DCF!$C$29+DCF!$C$30)/DCF!$C$32} -> 336.77973 | F22: {=(SUMPRODUCT(DCF!$I$14:$L$14/(1+$B22)^DCF!$I$15:$L$15)+DCF!$C$38*F$18/(1+$B22)^(DCF!$L$15+0.5)-DCF!$C$29+DCF!$C$30)/DCF!$C$32} -> 368.92645 | G22: {=(SUMPRODUCT(DCF!$I$14:$L$14/(1+$B22)^DCF!$I$15:$L$15)+DCF!$C$38*G$18/(1+$B22)^(DCF!$L$15+0.5)-DCF!$C$29+DCF!$C$30)/DCF!$C$32} -> 401.07316
B23: =B22+0.5% -> 0.099417386 | C23: {=(SUMPRODUCT(DCF!$I$14:$L$14/(1+$B23)^DCF!$I$15:$L$15)+DCF!$C$38*C$18/(1+$B23)^(DCF!$L$15+0.5)-DCF!$C$29+DCF!$C$30)/DCF!$C$32} -> 267.94368 | D23: {=(SUMPRODUCT(DCF!$I$14:$L$14/(1+$B23)^DCF!$I$15:$L$15)+DCF!$C$38*D$18/(1+$B23)^(DCF!$L$15+0.5)-DCF!$C$29+DCF!$C$30)/DCF!$C$32} -> 299.50958 | E23: {=(SUMPRODUCT(DCF!$I$14:$L$14/(1+$B23)^DCF!$I$15:$L$15)+DCF!$C$38*E$18/(1+$B23)^(DCF!$L$15+0.5)-DCF!$C$29+DCF!$C$30)/DCF!$C$32} -> 331.07547 | F23: {=(SUMPRODUCT(DCF!$I$14:$L$14/(1+$B23)^DCF!$I$15:$L$15)+DCF!$C$38*F$18/(1+$B23)^(DCF!$L$15+0.5)-DCF!$C$29+DCF!$C$30)/DCF!$C$32} -> 362.64136 | G23: {=(SUMPRODUCT(DCF!$I$14:$L$14/(1+$B23)^DCF!$I$15:$L$15)+DCF!$C$38*G$18/(1+$B23)^(DCF!$L$15+0.5)-DCF!$C$29+DCF!$C$30)/DCF!$C$32} -> 394.20726
